Workbook

Sheet הערות לקבלן
C1: כתב כמויות לשיפוץ דירה_ משפחת בן צור-אורן
C3: כתובת : קצין 5, רעננה | G3: מועד מיועד לתחילת השיפוץ: מרץ 2026
C4: קומה: 3 (כרגע ללא מעלית)
C5: שטח- כ- 123 מ"ר + 7 מ"ר מרפסת (כולל ממ"ד ומרפסת שמש שנוספו במסגרת תמ"א)
C6: תיאור כללי- דירת 3.5 חדרים + ממ"ד, בבנין המצוי בשלב סיום תמ"א 38/1, כיוון דרום/מזרח/צפון, דירה חזיתית לרחוב קצין
B10: להלן מפרט העבודות הנדרש לשיפוץ הדירה. יש למלא את המחירים החסרים. אין לבצע שינוי בכתב ובמפרט ההצעה.
B11: רשימה זו נועדה להרחיב את סט התוכניות המוגש ומצ"ב. יש להקפיד לעבור על סט התוכניות במקביל למפרט.
B12: כתב הכמויות נועד לשם הצעת מחיר בלבד ועל בסיס סט התוכניות. במעבר לתוכניות ביצוע ייתכנו שינויים באלמנטים השונים ובכמויות.
C14: סיכום | D14: מחיר | E14: הערות
B15: 1 | C15: הריסה | D15: ='הריסה '!F39 -> 49450
B16: 2 | C16: בניה | D16: =בניה!F16 -> 47100 | F16: 0
B17: 3 | C17: חשמל תאורה ותקשורת | D17: ='חשמל ותקשורת '!F36 -> 34860
B18: 4 | C18: אינסטלציה | D18: =אינסטלציה!F36 -> 40300
B19: 5 | C19: חיפוי ריצוף ואבן | D19: ='חיפוי וריצוף'!F31 -> 52040
B20: 6 | C20: טיח, צבע שפכטל | D20: ='טיח צבע ושפכטל'!F15 -> 24500
B21: 7 | C21: איטום חדרי רחצה | D21: 6000
B22: 8 | C22: דלתות | D22: ='דלתות וחלונות'!F9 -> 0
B23: 9 | C23: חלונות | D23: ='דלתות וחלונות'!F19 -> 0
B24: 10 | C24: חוץ | D24: ='חוץ ושונות'!F6 -> 0
B25: 11 | C25: שונות | D25: ='חוץ ושונות'!F15 -> 0
C26: סה"כ כללי (לפני הנחה) | D26: =SUM(D15:D25) -> 254250 | E26: מובהר כי הסה"כ בגליון זה ובסיכום כל גליון בנפרד, כולל פריטים אשר מוגדרים בגליונות כאופציונליים
C27: מע"מ | D27: =D26*1.17 -> 297472.5
C28: הנחה | D28: 0.0778 | E28: ההנחה בשיעור 7.8% תחול על על מחירי כל הפריטים הכלולים בהצעת המחיר.
C29: סה"כ אחרי הנחה ולפני מע"מ | D29: 236000
B31: באחריות הקבלן פיקוח על כל העבודות הנעשות באתר, כולל תיאומים בין בעלי המקצוע.
B32: העבודות יבוצעו בהתאם לתקנים ולדרישות התכנון.
B33: אספקת אריחים, כלי סניטציה, מקלחונים, נגרות- באחריות הלקוח.
B34: כל שאר חומרי העבודה והעזר הנדרשים לביצוע- באחריות קבלן.
B35: באחריות הקבלן השארת המקום נקי ומסודר בסיום כל שלב, שמירה על סביבת הבניין נקייה וקיום יחסי שכנות טובים עם הדיירים הסמוכים במהלך השיפוץ.
B36: יש להקפיד על שעות עבודה לפי חוקי ותקנות הרעש.
B37: באחריות הקבלן מסירת דירה נקייה עם סיום הפרויקט משאריות בניה ( לא כולל נקיון יסוד- שאינו כלול במחיר) וביצוע תיקונים נדרשים בתום הפרויקט.
B38: הכמויות המצויינות לא כוללות פחת

Sheet הריסה 
A1: פרק 1 | B1: הריסה
A2: סעיף | B2: פירוט | C2: יחידות | D2: כמות | E2: מחיר ליח' | F2: סה"כ | G2: הערות
B3: הריסות וחציבות בבטון/בלוקים/גבס
A4: 1.1 | B4: פירוק ופינוי קירות פנים בלוק 7-10 | C4: מ"א | D4: 33 | E4: 500 | F4: =E4*D4 -> 16500 | G4: ע"פ תוכנית הריסה.לרבות חגורות בטון אם קיימות בבניה, ניתוק וסילוק נק' מים וחשמל בקירות אלו
A5: 1.2 | B5: פירוק מחיצות גבס קיימות, לרבות מסלולים וניצבים מפלדה | C5: מ"א | D5: 2 | E5: 500 | F5: =E5*D5 -> 1000
A6: 1.3 | B6: שבירת תקרת בוידעם | C6: מ"ר | D6: 4 | E6: 1000 | F6: =E6*D6 -> 4000
A7: 1.4 | B7: הריסת מרצפי בטון קומפלט | C7: מ"ר | F7: =E7*D7 -> 0
A8: 1.5 | B8: חציבה/הגדלת פתחי קירות, לרבות עיבוד צורת הפתח ע"י בטון וטיח | C8: מ"ר | F8: =E8*D8 -> 0
A9: 1.6 | B9: פירוק תקרה אקוסטית/ גבס קיימת- | C9: מ"ר | F9: =E9*D9 -> 0 | G9: לרבות אלמנטי תלייה, גופי תאורה ובידוד במידה ויש
A10: 1.7 | B10: הריסת מעקה בנוי ומטוייח לרבות חגורות בטון | C10: מ"ר | F10: =E10*D10 -> 0
A11: 1.8 | B11: פירוק ופינוי עמוד קונסטרוקטיבי במטבח | C11: קומפלט | F11: =E11*D11 -> 0 | G11: בתכנון, הנחייה, פיקוח ואישור מהנדס
B12: פירוקים בריצוף וחיפוי
A13: 1.9 | B13: פירוק ופינוי ריצוף קיים | C13: מ"ר | D13: 105 | E13: 100 | F13: 10050 | G13: אופציונלי- למקרה שייוחלט על פירוק הריצוף ולא הדבקת ריצוף חדש על הריצוף הקיים
A14: 1.1 | B14: עקירת אריחי ריצוף כפול ופינוי כולל מצע - למכולת אשפה | C14: מ"ר | F14: =E14*D14 -> 0
A15: 1.11 | B15: פירוק קרמיקה/חרסינה מקירות שאינם מיועדים להריסה | C15: מ"ר | F15: =E15*D15 -> 0 | G15: חדר רחצה הורים, ילדים, מטבח - לרבות סיתות שכבת הטיט מהקיר
A16: 1.12 | B16: פירוק ופינוי פנלים קיימים | C16: קומפלט | F16: 0 | G16: כלול בהריסת הקירות
A17: 1.13 | B17: פירוק ופינוי פרקט למינציה חדר הורים | C17: מ"ר | F17: =E17*D17 -> 0
B18: פירוק אינסטלציה
A19: 1.14 | B19: פירוק אסלות קיימות עם כל אביזריהן | C19: יח' | D19: 1 | E19: 300 | F19: 300
A20: 1.15 | B20: פירוק כיורים קיימים מחרס/נירוסטה עם כל אביזריהם | C20: יח' | D20: 1 | E20: 150 | F20: 150
A21: 1.16 | B21: פירוק אמבטיה כולל כל האביזרים וניתוק מקווי מים ונקזים | C21: יח' | D21: 1 | E21: 2000 | F21: 2000 | G21: כולל סתימת פתחים לפי צורך
A22: 1.17 | B22: פירוק ברזי מקלחת קיימים כולל כל האביזרים וניתוק מקווי מים | C22: יח' | D22: 1 | E22: 100 | F22: 100 | G22: כולל סתימת פתחים לפי צורך
A24: 1.18 | B24: פירוק סוללות מים למים חמים וקרים כולל ניתוק מקווי מים | C24: יח' | D24: 2 | E24: 150 | F24: 150 | G24: כולל סתימת פתחים לפי צורך
A25: 1.19 | B25: פירוק משטח שיש במטבח בעומק עד 65 ס"מ | C25: מ"א | D25: 4 | F25: =E25*D25 -> 0
A26: 1.20 | B26: פירוק דוד מים חמים לרבות צנרת חשמל | C26: קומפלט | F26: =E26*D26 -> 0
A27: 1.21 | B27: פירוק מערכת דוד שמש דירתי לרבות קולטנים צנרת וחשמל | C27: קומפלט | F27: =E27*D27 -> 0
A28: 1.22 | B28: ניקוי ושטיפה של קולטן שמש דירתי | C28: קומפלט | F28: =E28*D28 -> 0
B29: פירוקים בעבודות נגרות ומסגרות
A30: 1.23 | B30: פירוק ופינוי דלתות פנים כולל משקופים | C30: יח' | D30: 6 | E30: 200 | F30: 1200
A31: 1.24 | B31: קיצור דלתות | C31: יח' | F31: =E31*D31 -> 0
A32: 1.25 | B32: פירוק פינוי ארונות חדרי שינה / חדרי ארונות | C32: קומפלט | F32: 8000 | H32: אופציונלי
A33: 1.26 | B33: פירוק ופינוי ארונות חדרי רחצה | C33: יח | F33: =E33*D33 -> 0 | H33: אופציונלי
A34: 1.27 | B34: פירוק ופינוי מטבח | C34: קומפלט | F34: 6000 | G34: כולל ארונות עליונים, תחתוניים, שיש, סניטציה | H34: אופציונלי
A35: 1.28 | B35: פירוק חלונות ומשקופים | C35: יח | F35: =E35*D35 -> 0
A36: 1.29 | B36: פירוק ופינוי דלת כניסה - עץ/ברזל / פלדלת | C36: יח' | F36: =E36*D36 -> 0
B37: כללי
A38: 1.30 | B38: פירוק ופינוי סורגים לחלונות | C38: יח' | F38: =E38*D38 -> 0
B39: סה"כ הריסה: | F39: =SUM(F4:F38) -> 49450
B41: ההריסה / הפירוק / הפינוי כוללים גם את פינוי הפסולת לאתר מורשה בהתאם לדרישות העירייה/מועצה
B42: בסיום שלב פירוק פתחים תבוצע סגירה זמנית נאותה של הפתחים כדי למנוע כניסה עד להרכבת חלונות ודלתות חדשים
...

Sheet בניה
A1: פרק 2 | B1: בניה
A2: סעיף | B2: פירוט | C2: יחידות | D2: כמות | E2: מחיר ליח' | F2: סה"כ | G2: הערות
A3: 2.1 | B3: בניית קירות ע"פ תוכנית בנייה כולל בידוד, ב-2 אופציות: | F3: =E3*D3 -> 0 | G3: ע"פ תוכנית בנייה. יש לתמחר בשתי אופציות-
A4: 2.1.1 | B4: שורת בלוקים | C4: מ״א | D4: 24 | E4: 350 | F4: =D4*E4 -> 8400 | G4: לא ברור
A5: 2.1.2 | B5: בניה בגבס מתאים לפי איזורי הדירה, כולל בידוד (צמר סלעים/זכוכית) | C5: מ"ר | D5: 68 | E5: 350 | F5: =D5*E5 -> 23800
A6: 2.2 | B6: בניית קיר כפול לדלת | C6: מ"ר | D6: 0 | F6: =E6*D6 -> 0 | G6: דלת סקריניו / הזזה - תסופק ע"י המזמין
A7: 2.3 | B7: התקנת קורת פלדה במקום העמוד שבוטל | C7: קומפלט | F7: =E7*D7 -> 0 | G7: בתכנון, הנחייה פיקוח ואישור מהנדס
A8: 2.4 | B8: הנמכות גבס לפי תוכנית | C8: מ"ר | D8: 28 | E8: 350 | F8: =E8*D8 -> 9800
A9: 2.5 | B9: בניית מעקה בלוק בטון חול עובי 7/10/25 גובה - X | C9: מ"ר | F9: =E9*D9 -> 0
A10: 2.6 | B10: בניית ספסל בחדר רחצה הורים- יצוק בטון | C10: קומפלט | D10: 1 | E10: 2000 | F10: 2000 | H10: אופציונלי
A11: 2.7 | B11: עיבוי קיר חדר רחצה כולל נישת סבונים | C11: מ"ר | F11: =E11*D11 -> 0 | G11: יש לבחון אופציה לחציבה בקיר קיים
A12: 2.8 | B12: סגירת פתחים - דלת/חלון | C12: מ"ר | F12: =E12*D12 -> 0
A13: 2.9 | B13: בניית דופן אמבטיה (160/70) מבלוק חלול עובי 7 גובה 42 + התקנת אמבטיה | C13: קומפלט | E13: 2500 | F13: 2500
A14: 2.10 | B14: תוספת עבור החלקת רצפת בטון- הליקופטר | C14: מ"ר | F14: =E14*D14 -> 0
A15: 2.10 | B15: קידוח פתח 5 צול בקיר חצוני להתקנת ונטה בח. אמבטיה הורים | D15: 1 | E15: 600 | F15: 600
B16: סה"כ בניה: | F16: =SUM(F3:F15) -> 47100
B19: כל המחירים לעיל הינם לפני הנחה בשיעור 7.8%

Sheet חשמל ותקשורת 
A1: פרק 3 | B1: חשמל, תאורה ותקשורת
A2: סעיף | B2: פירוט | C2: יחידות | D2: כמות | E2: מחיר ליח' | F2: סה"כ | G2: הערות
B3: חשמל ותקשורת
A4: 3.1 | B4: העתקת ארון חשמל | C4: יח' | D4: 1 | F4: 1500 | G4: ע"פ הנחיית חשמלאי מוסמך
A5: 3.15 | B5: החלפת תשתית החשמל בכל הדירה (למעט ממ"ד ומרפסת)
A6: 3.2 | B6: לוח חשמל תלת פאזי + ביקורת חברת חשמל | C6: יח' | D6: 1 | F6: 7000
A7: 3.3 | B7: נקודת שקע חדשה | C7: יח' | D7: 22 | E7: 380 | F7: =E7*D7 -> 8360 | G7: לשים לב למוגנות מים בחדרים רטובים
A8: 3.4 | B8: הגדלת שקע מיזוג לתלת / יחיד לזוג | C8: יח' | D8: 1 | E8: 900 | F8: =E8*D8 -> 900
A9: 3.5 | B9: נק' צינור השחלה (קוברה) בין מכשירים | C9: יח' | D9: 2 | E9: 400 | F9: =E9*D9 -> 800 | G9: לעדכן מרחק עבור צינור ההשחלה- מנק' לנק'
A10: 3.6 | B10: נקודת סימה בוקס 4 שקעים (טלוויזיה+טלפון+מחשב) | C10: יח' | D10: 1 | E10: 1200 | F10: =E10*D10 -> 1200
A11: 3.7 | B11: ביטול נק' קיימת | C11: יח' | F11: =E11*D11 -> 0
A12: 3.8 | B12: שינוי מיקום נק' קיימת עד 1 מטר | C12: יח' | D12: 1 | F12: 0
A13: 3.65 | B13: קודת סימה בוקס 6 שקעים (טלוויזיה+טלפון+מחשב) | D13: 1 | E13: 1400 | F13: 1400 | G13: לדבר על תמחור שקעים כפולים
A14: 3.9 | B14: התקנת תלת פאזי | C14: יח' | D14: 1 | E14: 900 | F14: =E14*D14 -> 900
A15: 3.10 | B15: התקנת אביזר טיימר לדוד מים | C15: יח' | D15: 1 | E15: 600 | F15: =E15*D15 -> 600
A16: 3.11 | B16: נקודת כוח מכשירים מטבח - שקע כפול | C16: יח' | D16: 1 | E16: 550 | F16: =E16*D16 -> 550
A17: 3.12 | B17: נקודת כוח קו נפרד מטבח- תנור, מיקרו, מקרר, מדיח, | C17: יח' | D17: 4 | E17: 450 | F17: =E17*D17 -> 1800
A18: 3.13 | B18: נקודת כוח קו נפרד למייבש,מכונת כביסה | C18: יח' | D18: 2 | E18: 450 | F18: =E18*D18 -> 900
A19: 3.14 | B19: נקודת כוח קו נפרד לדוד מים | C19: יח' | D19: 1 | E19: 450 | F19: =E19*D19 -> 450
A20: 3.15 | B20: נקודת כוח קו נפרד לתנור אמבטיה | C20: יח' | D20: 2 | E20: 450 | F20: =E20*D20 -> 900
A21: 3.16 | B21: נקודת טלפון בזק כולל כבל ושקע | C21: יח' | D21: 1 | E21: 450 | F21: =E21*D21 -> 450
A22: 3.17 | B22: נקודת הכנה לרמקול | C22: יח' | D22: 2 | F22: =E22*D22 -> 0
A23: 3.18 | B23: תוספת למוגן מים הרמטי | C23: יח' | D23: 3 | E23: 100 | F23: =E23*D23 -> 300
A24: 3.19 | B24: נק' לתריס חשמלי כולל נק' הדלקה | C24: יח' | D24: 1 | F24: =E24*D24 -> 0
A25: 3.20 | B25: אינטרקום | C25: יח' | D25: 1 | F25: =E25*D25 -> 0
A26: 3.21 | B26: נק' תקשורת אינטרנט | C26: יח' | D26: 1 | E26: 350 | F26: =E26*D26 -> 350 | G26: במידת הצורך הטמעת צנרת מיזוג בקירות
A27: 3.22 | B27: נק' פעמון + פעמון סטנדרטי | C27: יח' | D27: 0 | F27: =E27*D27 -> 0
A28: 3.23 | B28: נקודת כוח מכשירים | C28: יח' | D28: 0 | F28: =E28*D28 -> 0
B29: תאורה
A30: 3.24 | B30: נקודת מאור קיר או תקרה | C30: יח' | D30: 10 | E30: 350 | F30: =E30*D30 -> 3500 | G30: מפסקים בהתאם
A31: 3.25 | B31: נקודת מאור חילוף | C31: יח' | D31: 4 | E31: 400 | F31: =E31*D31 -> 1600
A32: 3.26 | B32: נקודת מאור - תוספת למאוורר | C32: יח' | D32: 4 | E32: 350 | F32: =E32*D32 -> 1400
A33: 3.27 | B33: הזזת נק' מאור עד 1 מ' | C33: יח' | D33: 1 | F33: =E33*D33 -> 0
A34: 3.28 | B34: ביטול נק' מאור קיימת | C34: יח' | D34: 1 | F34: =E34*D34 -> 0
A35: 3.29 | B35: התקנת גוף תאורה (רגיל. לא מורכב) | C35: יח' | D35: 1 | F35: =E35*D35 -> 0
B36: סה"כ תאורה תקשורת וחשמל | C36: יח' | F36: =SUM(F4:F35) -> 34860
B37: כל האביזרים כגון שקעים ומתגי הדלקה חברת גביס' (או שווה ערך) וכלולים במחיר הנק'.
B38: לפני תחילת העבודה יש לעבור עם המזמין ולוודא מיקום סופי של אביזרים.
B39: גופי התאורה יסופקו ע"י המזמין
B40: לא תומחרו התקנות גופי תאורה
...

Sheet אינסטלציה
A1: פרק 4 | B1: אינסטלציה
A2: סעיף | B2: פירוט | C2: יחידות | D2: כמות | E2: מחיר ליח' | F2: סה"כ | G2: הערות
B3: מטבח
A4: 4.1 | B4: נקודת מים לכיור- חמים קרים | C4: יח' | D4: 1 | E4: 2500 | F4: 2500
A5: 4.2 | B5: הכנה לחיבור מדיח כלים, ברז שופך מצופה כרום, צינור גומי למדיח וכל החיבורים הנדרשים למע' הביוב והמים | C5: יח' | D5: 1 | E5: 2000 | F5: 2000
A6: 4.3 | B6: נקודת מים למקרר | C6: יח' | D6: 1 | E6: 1500 | F6: 1500
A7: 4.4 | B7: נקודת מים לתמי 4 | C7: יח' | D7: 1 | E7: 1500 | F7: 1500
A8: 4.5 | B8: הכנת תשתית גז כולל ביקורת טכנאי גז | C8: קומפ' | D8: 1 | E8: 1250 | F8: 1250
B9: חדר רחצה - הורים
A10: 4.6 | B10: נקודה + התקנת אסלה תלויה עם מיכל הדחה סמוי למים קרים וביוב. | C10: יח' | D10: 1 | E10: 4900 | F10: 4900 | G10: כולל חיזוק וביטון הניאגרה וסגירה בגבס.
A11: 4.7 | B11: התקנת אסלה רגילה (מונובלוק) מיכל הדחה וברז מהקיר | C11: יח' | F11: =E11*D11 -> 0
A12: 4.65 | B12: נקודה + מערכת קיר מיני 3 דרך לשטיפה ליד אסלה | D12: 1 | E12: 2500 | F12: 2500 | G12: אופציונלי
A13: 4.8 | B13: נק' מים לכיור רחצה - חמים קרים- ברז מהקיר | C13: יח' | D13: 1 | E13: 2500 | F13: 2500 | G13: לתת מחיר אופציונלי לברז פרח
A14: 4.9 | B14: נק' מים למקלחת- מערכת קיר 4 דרך מים חמים-קרים + ראש מקלחת, מזלף יד ומחסום רצפה. | C14: יח' | D14: 1 | E14: 2500 | F14: 2500
B15: חדר רחצה ילדים
A16: 4.10 | B16: נק'+התקנת אסלה תלויה עם מיכל הדחה סמוי למים קרים וביוב. | C16: יח' | D16: 1 | E16: 4900 | F16: 4900 | G16: כולל חיזוק וביטון הניאגרה וסגירה בגבס.
A17: 4.11 | B17: התקנת אסלה רגילה (מונובלוק) מיכל הדחה וברז מהקיר | C17: יח' | F17: =E17*D17 -> 0
A18: 4.12 | B18: נק' מים לכיור רחצה - חמים קרים- ברז מהקיר | C18: יח' | D18: 1 | E18: 2500 | F18: 2500 | G18: לתת מחיר אופציונלי לברז פרח
A19: 4.13 | B19: נק' מים למקלחת- מערכת קיר 4 דרך מים חמים-קרים + ראש מקלחת, מזלף יד ומחסום רצפה. | C19: יח' | D19: 0 | F19: =E19*D19 -> 0 | G19: לעדכן במידה ו-3 דרך
A20: 4.14 | B20: נק' מים לאמבטיה- מערכת קיר 4 דרך מים חמים-קרים + פיית מילוי, מזלף יד והתקנת האמבטיה 170/70 | C20: יח' | D20: 1 | E20: 2500 | F20: 2500
B21: שירותי אורחים
A22: 4.15 | B22: נקודה + התקנת אסלה תלויה עם מיכל הדחה סמוי למים קרים וביוב. | C22: יח' | F22: =E22*D22 -> 0 | G22: כולל חיזוק וביטון הניאגרה וסגירה בגבס.
A23: 4.16 | B23: התקנת אסלה רגילה (מונובלוק) מיכל הדחה וברז מהקיר | C23: יח' | F23: =E23*D23 -> 0
A24: 4.17 | B24: נק' מים לכיור רחצה - חמים קרים | C24: יח' | F24: =E24*D24 -> 0 | G24: יש לציין במידה והברז מהקיר
A25: 4.18 | B25: העברת נק' ביובי 4 צול | F25: =E25*D25 -> 0
B26: חדר שירות
A27: 4.19 | B27: נק' מים לכיור רחצה - חמים קרים | C27: יח' | D27: 0 | F27: =E27*D27 -> 0
A28: 4.20 | B28: הכנה לחיבור מכונת כביסה, ברז שופך מצופה כרום, כל החיבורים הנדרשים למע' הביוב והמים. כולל אספקת סוללה | C28: יח' | D28: 1 | E28: 2500 | F28: 2500
A29: 4.21 | B29: ניקוז למייבש כביסה | C29: יח' | D29: 1 | E29: 1500 | F29: 1500
A30: 4.22 | B30: חיבור מים קרים לדוד מים | C30: יח' | D30: 1 | E30: 2500 | F30: 2500 | G30: ????
B31: חוץ
A32: 4.23 | B32: נק' מים חיצוניות (קרים) | C32: יח' | D32: 1 | E32: 1500 | F32: 1500
A33: 4.24 | B33: הכנת לתשתית השקיית גינה | C33: יח' | D33: 1 | F33: =E33*D33 -> 0
A34: 4.25 | B34: צנרת מים לדוד חשמלי | C34: יח' | D34: 1 | F34: =E34*D34 -> 0
A35: 4.3 | B35: הכנת תשתית גז כולל ביקורת טכנאי גז | C35: יח' | D35: 1 | E35: 1250 | F35: 1250
B36: סה"כ אינסטלציה | F36: =SUM(F4:F35) -> 40300
A38: כל נק' התברואה המצויינות כוללות את כל הצנרת הנדרשת, הרכבת כלים סניטריים, הסוללות וכל הנדרש לחיבור למע' הביוב והמים,
A39: חציבה בקירות ותיקונם לאחר ההתקנה.
A40: כולל אביזרים וחומר שחור. ברזי ניל וסיפונים- באחריות הקבלן
A41: כל האביזרים הסניטריים והברזים יסופקו ע"י המזמין. באחריות הקבלן בדיקת תקינות הכלים הסניטריים ובכל בעיה יש לעדכן את הלקוח
...

Sheet חיפוי וריצוף
A1: פרק 5 | B1: ריצוף, חיפוי ואבן
A2: סעיף | B2: פירוט | C2: יחידות | D2: כמות | E2: מחיר ליח' | F2: סה"כ | G2: הערות
B3: ריצוף
A4: 5.1 | B4: ריצוף כללי בכל השטח הציבורי- גרניט פורצלן 80/80 או 100/100לרבות פנלים | C4: מ"ר | D4: 60 | E4: 330 | F4: =D4*E4 -> 19800
A5: 5.2 | B5: ריצוף שירותים וחדרי אמבטיה גרניט פורצלן אנטי סליפ 60/60 או 120/60 | C5: מ"ר | D5: 13 | E5: 330 | F5: =D5*E5 -> 4290
A6: 5.3 | B6: ריצוף חדר רחצההורים גרניט פורצלן 30/30 לרבות פנלים | C6: מ"ר | F6: =E6*D6 -> 0 | G6: לעדכן גודל אריח
A7: 5.4 | B7: ריצוף חדר רחצה ילדים גרניט פורצלן 30/30 לרבות פנלים | C7: מ"ר | F7: =E7*D7 -> 0 | G7: לעדכן גודל אריח
A8: 5.5 | B8: ריצוף חדרי שינה/ילדים גרניט פורצלן 60/60 סוג ב' ללא פנלים | C8: מ"ר | D8: 36 | E8: 330 | F8: =D8*E8 -> 11880
A9: 5.6 | B9: ריצוף באריחי שיש/אבן טבעית לרבות שיפולים | C9: מ"ר | F9: =E9*D9 -> 0
A10: 5.7 | B10: ריצוף חוץ אנטיסליפ כולל יציקות ומילוי אדמת גן | C10: מ"ר | F10: =E10*D10 -> 0
A11: 5.8 | B11: הכנת תשתית מדרגות | C11: קומפלט | F11: =E11*D11 -> 0
A12: 5.9 | B12: יצירת שיפועים והנמכות נדרשים עבור ניקוז בהתאם לתוכנית. | C12: קומפלט | F12: =E12*D12 -> 0 | G12: שימוש בפסי ניקל בהתאם לצורך.
A13: 5.10 | B13: התקנת פנלים (שקועים- בקו 0 ) | C13: מ"א | F13: 3000
A14: 5.11 | B14: פרקטים- יסופקו ע"י המזמין + פנלים. באחריות הקבלן הכנת הבית להתקנת הפרקט (התקנה ע"י נתקיןם פרקטים / באחריות הקבלן) | F14: =E14*D14 -> 0
A15: 5.12 | B15: ביצוע מדה מתפלסת לאחר הנחת הצנרת החדשה לפי הנדרש | C15: מ"ר | F15: =E15*D15 -> 0 | G15: עובי 1 ס"מ כהכנה לפרקט/שטיח.
A16: 5.13 | B16: תיקוני ריצוף בקירות שנשברו | C16: קומפלט | F16: 2000 | G16: ?????
A17: 5.14 | B17: הריצוף יבוצע בהדבקה על גבי ריצוף קיים. העבודה תתבצע בשלמות כולל חומר שחור | F17: =E17*D17 -> 0
A18: 5.15 | B18: פירוק ריצוף קיים+פינוי חצץ/סומסום עבור ייבוש הרצפה לפני התקנת ריצוף חדש. בהתאם הכנת תשתית חדשה לריצוף- אספקת מצע יבש ופיזורו | C18: קומפלט | G18: להסביר (מה נכלל בפירוק בפרק הפירוק)
B19: חיפוי קיר
A20: 5.16 | B20: חיפוי קיר מקלחת הורים- אריחים 90/30 או 120/60 | C20: מ"ר | D20: 11 | E20: 330 | F20: =D20*E20 -> 3630
A21: 5.17 | B21: חיפוי קיר מקלחת ילדים- אריחים 30/90 או 120/60 | C21: מ"ר | D21: 18 | E21: 330 | F21: =D21*E21 -> 5940
A22: 5.18 | B22: חיפוי קיר שרותי אורחים- אריחים 20/90 | C22: מ"ר | F22: =E22*D22 -> 0
A23: 5.19 | B23: חיפוי קיר מטבח- אריחים 120/60 | C23: מ"ר | D23: 3 | E23: 500 | F23: =D23*E23 -> 1500 | G23: אופציונלי
A24: 5.20 | B24: התקנת פס דקור קרמיקה | C24: מ"א | F24: =E24*D24 -> 0
B25: משטחי אבן ושיש
A26: 5.21 | B26: משטח אבן שיש חברון עובי 2 ס"מ כולל מדידה, הרכבה והובלה | C26: מ"ר | F26: =E26*D26 -> 0 | G26: לעדכן סוג אבן
A27: 5.22 | B27: משטחי קוורץ אבן קיסר/דקטון (דגם ימסר בהמשך) בעובי 2/4 ס"מ | C27: מ"א | F27: =E27*D27 -> 0 | G27: כולל מדידה, הובלה והרכבה
A28: 5.23 | B28: גמר סרגל רגיל | C28: מ"א | F28: =E28*D28 -> 0
A29: 5.24 | B29: חיתוך פתח לכיור + ברז | C29: יח' | F29: =E29*D29 -> 0
A30: 5.25 | B30: אדני חלון מלוחות שיש "חברוני" מלוטש בעובי 3 ס"מ | C30: מ"א | F30: =E30*D30 -> 0 | G30: לעדכן סוג אבן
B31: סה"כ ריצוף חיפוי ואבן : | F31: =SUM(F4:F30) -> 52040
A33: כללי
A34: הצבת מסחררי אוויר לייבוש הבטון (במידת הצורך- למחוק במידה ומיותר)
A35: אריחים יסופקו ע"י הלקוח
A36: שינוע מרצפות, אריחים, קרמיקה מהמדרכה לתוך הבית + תיאום אספקת האריחים מול הלקוחות- באחריות הקבלן
A37: יש לוודא חיתוכי גרונגים יפים
A38: אספקה והתקנת פסי ניקל/אלומיניום לדלתות/פינות - בהתאם לצורך
A39: אספקת רובה אקרילית ע"י הקבלן בהתאם לחברה+ מס' צבע שימסר ע"י המעצבת/הלקוח
A40: עיבוד רובה אקרילית חדשה בפוגות חיפויי קיר קיימים, לרבות ניקוי הפוגות.
B41: כל המחירים לעיל הינם לפני הנחה בשיעור 7.8%
...

Sheet Sheet2

Sheet Sheet3

Sheet טיח צבע ושפכטל
A1: פרק 6 | B1: טיח, צבע, שפכטל
A2: סעיף | B2: פירוט | C2: יחידות | D2: כמות | E2: מחיר ליח' | F2: סה"כ | G2: הערות
B3: צבע
A4: 3.1 | B4: צבע פנים סופרקריל בהתאם לחלוקת הגוונים שתימסר ע"י המזמין בהמשך. קומפלט לכל הדירה | C4: קומפלט | F4: 12000 | G4: כולל תיקונים לאחר התקנת נגרות ודלתות. עד 4 גוונים שונים.
A5: 3.2 | B5: צביעת תקרות פוליסיד לבן (חדרי רחצה- נגד עובש) | C5: קומפלט | F5: 6000
A6: 3.3 | B6: צביעת דלתות ומשקופים- פוליאור | C6: יח' | F6: =E6*D6 -> 0
A7: 3.4 | B7: חידוש צבע סורגים | C7: קומפלט | F7: =E7*D7 -> 0
B8: טיח
A9: 3.5 | B9: תיקוני טיח וגליפים בכל מקום בו בוצעו הריסות/קירות חדשים/פירוק פנלים/ הונחה תשתית | C9: קומפלט | F9: 5000
A10: 3.6 | B10: תיקוני טיח סביב דלתות חלונות עפי הנדרש | C10: קומפלט | F10: 1500
A11: 3.7 | B11: פינות טיח גרמניות בכל פינה נדרשת | C11: קומפלט | F11: =E11*D11 -> 0
A12: 3.8 | B12: נא לתמחר בנפרד, כאופציה, תוספת עלות החלקת קירות בשפכטל אמריקאי לכל הבית | C12: קומפלט | G12: 2 ידיים לפחות
B13: שליכט צבעוני
A14: 3.9 | B14: יש לתתת מחיר אינדקטיבי לצביעה מ"ר בשליכט פיגמנטי אקרילי בגימור עדין | C14: מ"ר
B15: סה"כ טיח שליכט וצבע: | F15: =SUM(F4:F14) -> 24500
A18: הערות
A19: העבודה כוללת את כל ההכנות הנדרשות לביצוע עבודת הצבע לפי הוראות יצרן, כולל מס' שכבות נדרש
A20: לפני תחילת עבודה יש להסיר צבע רופף, לפתוח סדקים קיימים ולמלא אותם בסיליקון, להוציא מסמרים, ברזלים, חוטי טלפון מיותרים וכד'
A21: לפני תחילת עבודה יש לשים מסקנטייפ על כל הפנלים והסרגלים בצורה מוקפדת
A22: עטיפה מושלמת של הבית כולל קרטונים ברצפה וניילונים לכל הדירה
A23: בקירות בהם יש טפט- יש לקלף את הטפט לפני תחילת עבודה ולהכין את הקיר לצביעה
A24: אספקת צבע, השליכט הצבעוני וכל הנדרש- באחריות הקבלן לפי דרישת הלקוח
B35: שפכטל אמריקאי | C35: 150 | D35: למ״ר | E35: שני ידיים
B36: שליכט צבעוני | C36: 200 | D36: למ״ר

Sheet איטום
A1: פרק 7 | B1: איטום חדרי רחצה
A2: סעיף | B2: פירוט | C2: יחידות | D2: כמות | E2: מחיר ליח' | F2: סה"כ | G2: הערות
A3: 7.1 | B3: איטום חדרי רחצה- אמבטיה ושירותים לפני ריצוף: כולל בדיקת הצפה | C3: יח' | D3: 9 | F3: =E3*D3 -> 0
A4: 7.2 | B4: הוצאת חול עד לרתפת בטון+ רולטקות בטון בפינות | C4: קומפלט | F4: =E4*D4 -> 0
A5: 7.3 | B5: מריחת סיקה טופ 107 למניעת עובש ופטריות ב-2 שכבות | C5: קומפלט | F5: =E5*D5 -> 0
A6: 7.4 | B6: הכנת איטום פתחים לקליטת חלונות חדשים לאחר פירוק | C6: יח' | F6: =E6*D6 -> 0
B7: סה"כ איטום: | F7: =SUM(F3:F6) -> 0

Sheet דלתות וחלונות
A1: פרק 8 | B1: דלתות ומפתחים
A2: סעיף | B2: פירוט | C2: יחידות | D2: כמות | E2: מחיר ליח' | F2: סה"כ | G2: הערות
A3: 8.1 | B3: התקנת משקופים עיוורים | C3: יח' | F3: =E3*D3 -> 0
A4: 8.2 | B4: אספקה והתקנה דלתות פנים MDF פתיחה כנף לצבע סטנדרט | C4: יח' | F4: =E4*D4 -> 0 | G4: כולל משקופים. מפרט גדלי פתחים:
A5: 8.3 | B5: אספקה והתקנה דלתות פנים MDF הזזה כנף לצבע סטנדרט | C5: יח' | F5: =E5*D5 -> 0 | G5: כולל משקופים. מפרט גדלי פתחים:
A6: 8.4 | B6: אספקה והתקנת דלתות פלדלת חוץ סטנדרטיות כולל משקוף | C6: יח' | F6: =E6*D6 -> 0 | G6: מפרט גדלי פתחים
A7: 8.5 | B7: קיצור דלתות קיימות בדירה עבור פרקט | C7: יח' | F7: =E7*D7 -> 0 | G7: קיצור בתחתית הדלת בהתאם לדרישות הפרקט
A8: 8.6 | B8: קיצור דלת ממ"ד | C8: יח' | F8: =E8*D8 -> 0
B9: סה"כ דלתות : | F9: =SUM(F3:F8) -> 0
A13: פרק 9 | B13: מפתחים- אלומיניום/ברזל
A14: סעיף | B14: פירוט | C14: יחידות | D14: כמות | E14: מחיר ליח' | F14: סה"כ | G14: הערות
A15: 9.1 | B15: התקנת משקופים עיוורים | C15: יח' | F15: =E15*D15 -> 0
A16: 9.2 | B16: מסגרות אלומיניום/ברזל- לפי תוכנית | C16: קומפלט | F16: =E16*D16 -> 0
A17: 9.3 | B17: סורג קבוע לחלונות | C17: יח' | F17: =E17*D17 -> 0 | G17: לציין דגם + גוון
A18: 9.4 | B18: תיקוני חלונות/תריסים קיימים | C18: יח' | F18: =E18*D18 -> 0
B19: סה"כ אלומיניום/ברזל : | F19: =SUM(F15:F18) -> 0

Sheet חוץ ושונות
A1: פרק 10 | B1: חוץ
A2: סעיף | B2: פירוט | C2: יחידות | D2: כמות | E2: מחיר ליח' | F2: סה"כ | G2: הערות
A3: 10.1 | B3: איטום ותיקונים בהתאם לשבירות | C3: קומפלט | D3: 0 | F3: =E3*D3 -> 0
A4: 10.2 | B4: יישום שליכט צבעוני | C4: קומפלט | D4: 0 | F4: =E4*D4 -> 0 | G4: כולל קילוף טיח קיים ויישום פריימר
A5: 10.3 | B5: חיבור לגז כולל ברז(מטבח חיצוני) | C5: יח' | D5: 0 | F5: =E5*D5 -> 0
B6: סה"כ חוץ: | D6: 0 | F6: =SUM(F3:F5) -> 0
A10: פרק 11 | B10: שונות
A11: סעיף | B11: פירוט | C11: יחידות | D11: כמות | E11: מחיר ליח' | F11: סה"כ | G11: הערות
D12: 0 | F12: =E12*D12 -> 0
D13: 0 | F13: =E13*D13 -> 0
D14: 0 | F14: =E14*D14 -> 0
B15: סה"כ חוץ: | D15: 0 | F15: =SUM(F12:F14) -> 0
A17: תוספות נדרשות ע"י הלקוח
